2021-03-20 21:31:10,592 - ERROR - csvmat.py:main method exception. Detailed: FileNotFoundError(2, 'No such file or directory')
Traceback (most recent call last):
  File "C:\Users\joonl\Data\Data-Visualization-MAPS\AppProto\app_proto\app\scripts_dev\logger.py", line 36, in wrapper
    return func(*args, **kwargs)
  File ".\process.py", line 163, in main
    processFile(cmdLineArgs)
  File ".\process.py", line 157, in processFile
    _handlePreCalculate(cmdLineArgs)
  File ".\process.py", line 136, in _handlePreCalculate
    return precalcs.handlePreCalculate(cmdLineArgs)
  File "C:\Users\joonl\Data\Data-Visualization-MAPS\AppProto\app_proto\app\scripts_dev\precalcs.py", line 334, in handlePreCalculate
    preCalcDataPath = _preCalcAndSave(cmdLineArgs)
  File "C:\Users\joonl\Data\Data-Visualization-MAPS\AppProto\app_proto\app\scripts_dev\precalcs.py", line 331, in _preCalcAndSave
    _savePreCalcDataFrame(dataFrame, cmdLineArgs)
  File "C:\Users\joonl\Data\Data-Visualization-MAPS\AppProto\app_proto\app\scripts_dev\precalcs.py", line 24, in _savePreCalcDataFrame
    _savePandasDataFrame(preProcessDataFrame, newDataFilePath)
  File "C:\Users\joonl\Data\Data-Visualization-MAPS\AppProto\app_proto\app\scripts_dev\precalcs.py", line 16, in _savePandasDataFrame
    pandasHelper.savePandasDataFrame(dataFrame, newDataFilePath)
  File "C:\Users\joonl\Data\Data-Visualization-MAPS\AppProto\app_proto\app\scripts_dev\helpers\pandasHelper.py", line 26, in savePandasDataFrame
    df.to_csv(filePath)
  File "C:\Users\joonl\AppData\Local\Packages\PythonSoftwareFoundation.Python.3.8_qbz5n2kfra8p0\LocalCache\local-packages\Python38\site-packages\pandas\core\generic.py", line 3170, in to_csv
    formatter.save()
  File "C:\Users\joonl\AppData\Local\Packages\PythonSoftwareFoundation.Python.3.8_qbz5n2kfra8p0\LocalCache\local-packages\Python38\site-packages\pandas\io\formats\csvs.py", line 185, in save
    f, handles = get_handle(
  File "C:\Users\joonl\AppData\Local\Packages\PythonSoftwareFoundation.Python.3.8_qbz5n2kfra8p0\LocalCache\local-packages\Python38\site-packages\pandas\io\common.py", line 493, in get_handle
    f = open(path_or_buf, mode, encoding=encoding, errors=errors, newline="")
FileNotFoundError: [Errno 2] No such file or directory: 'C:\\Users\\joonl\\AppData\\Roaming\\Electron\\save_files\\test2\\gm14_167aprhcalcs.csv'
2021-03-29 02:55:19,842 - ERROR - csvmat.py:main method exception. Detailed: KeyError('A')
Traceback (most recent call last):
  File "/Users/joonyounglee/Code/Data-Visualization-MAPS/AppProto/app_proto/app/scripts_dev/logger.py", line 36, in wrapper
    return func(*args, **kwargs)
  File "/Users/joonyounglee/Code/Data-Visualization-MAPS/AppProto/app_proto/app/scripts_dev/process.py", line 163, in main
    processFile(cmdLineArgs)
  File "/Users/joonyounglee/Code/Data-Visualization-MAPS/AppProto/app_proto/app/scripts_dev/process.py", line 156, in processFile
    cmdLineArgs = _addOrigFilePandasDataFrame(cmdLineArgs)
  File "/Users/joonyounglee/Code/Data-Visualization-MAPS/AppProto/app_proto/app/scripts_dev/process.py", line 142, in _addOrigFilePandasDataFrame
    origFilePandasDataFrame = _getOrigFilePandasDataFrame(cmdLineArgs)
  File "/Users/joonyounglee/Code/Data-Visualization-MAPS/AppProto/app_proto/app/scripts_dev/process.py", line 127, in _getOrigFilePandasDataFrame
    return _getPandasDataFrameFromFile(origDataFilePath)
  File "/Users/joonyounglee/Code/Data-Visualization-MAPS/AppProto/app_proto/app/scripts_dev/process.py", line 119, in _getPandasDataFrameFromFile
    return pandasDataFrameProcessor(filePath)
  File "/Users/joonyounglee/Code/Data-Visualization-MAPS/AppProto/app_proto/app/scripts_dev/process.py", line 84, in _handleMATConversionToPandasDataFrame
    parsedMatFileData = _getParsedMatFileData(filePath)
  File "/Users/joonyounglee/Code/Data-Visualization-MAPS/AppProto/app_proto/app/scripts_dev/process.py", line 80, in _getParsedMatFileData
    parsedMatFileData = _parseMatFileData(rawMatFileData)
  File "/Users/joonyounglee/Code/Data-Visualization-MAPS/AppProto/app_proto/app/scripts_dev/process.py", line 42, in _parseMatFileData
    shape=data[header].shape
KeyError: 'A'
2021-03-29 02:58:29,471 - ERROR - csvmat.py:main method exception. Detailed: KeyError('A')
Traceback (most recent call last):
  File "/Users/joonyounglee/Code/Data-Visualization-MAPS/AppProto/app_proto/app/scripts_dev/logger.py", line 36, in wrapper
    return func(*args, **kwargs)
  File "/Users/joonyounglee/Code/Data-Visualization-MAPS/AppProto/app_proto/app/scripts_dev/process.py", line 163, in main
    processFile(cmdLineArgs)
  File "/Users/joonyounglee/Code/Data-Visualization-MAPS/AppProto/app_proto/app/scripts_dev/process.py", line 156, in processFile
    cmdLineArgs = _addOrigFilePandasDataFrame(cmdLineArgs)
  File "/Users/joonyounglee/Code/Data-Visualization-MAPS/AppProto/app_proto/app/scripts_dev/process.py", line 142, in _addOrigFilePandasDataFrame
    origFilePandasDataFrame = _getOrigFilePandasDataFrame(cmdLineArgs)
  File "/Users/joonyounglee/Code/Data-Visualization-MAPS/AppProto/app_proto/app/scripts_dev/process.py", line 127, in _getOrigFilePandasDataFrame
    return _getPandasDataFrameFromFile(origDataFilePath)
  File "/Users/joonyounglee/Code/Data-Visualization-MAPS/AppProto/app_proto/app/scripts_dev/process.py", line 119, in _getPandasDataFrameFromFile
    return pandasDataFrameProcessor(filePath)
  File "/Users/joonyounglee/Code/Data-Visualization-MAPS/AppProto/app_proto/app/scripts_dev/process.py", line 84, in _handleMATConversionToPandasDataFrame
    parsedMatFileData = _getParsedMatFileData(filePath)
  File "/Users/joonyounglee/Code/Data-Visualization-MAPS/AppProto/app_proto/app/scripts_dev/process.py", line 80, in _getParsedMatFileData
    parsedMatFileData = _parseMatFileData(rawMatFileData)
  File "/Users/joonyounglee/Code/Data-Visualization-MAPS/AppProto/app_proto/app/scripts_dev/process.py", line 42, in _parseMatFileData
    shape=data[header].shape
KeyError: 'A'
2021-03-29 02:59:41,806 - ERROR - csvmat.py:main method exception. Detailed: KeyError('A')
Traceback (most recent call last):
  File "/Users/joonyounglee/Code/Data-Visualization-MAPS/AppProto/app_proto/app/scripts_dev/logger.py", line 36, in wrapper
    return func(*args, **kwargs)
  File "/Users/joonyounglee/Code/Data-Visualization-MAPS/AppProto/app_proto/app/scripts_dev/process.py", line 163, in main
    processFile(cmdLineArgs)
  File "/Users/joonyounglee/Code/Data-Visualization-MAPS/AppProto/app_proto/app/scripts_dev/process.py", line 156, in processFile
    cmdLineArgs = _addOrigFilePandasDataFrame(cmdLineArgs)
  File "/Users/joonyounglee/Code/Data-Visualization-MAPS/AppProto/app_proto/app/scripts_dev/process.py", line 142, in _addOrigFilePandasDataFrame
    origFilePandasDataFrame = _getOrigFilePandasDataFrame(cmdLineArgs)
  File "/Users/joonyounglee/Code/Data-Visualization-MAPS/AppProto/app_proto/app/scripts_dev/process.py", line 127, in _getOrigFilePandasDataFrame
    return _getPandasDataFrameFromFile(origDataFilePath)
  File "/Users/joonyounglee/Code/Data-Visualization-MAPS/AppProto/app_proto/app/scripts_dev/process.py", line 119, in _getPandasDataFrameFromFile
    return pandasDataFrameProcessor(filePath)
  File "/Users/joonyounglee/Code/Data-Visualization-MAPS/AppProto/app_proto/app/scripts_dev/process.py", line 84, in _handleMATConversionToPandasDataFrame
    parsedMatFileData = _getParsedMatFileData(filePath)
  File "/Users/joonyounglee/Code/Data-Visualization-MAPS/AppProto/app_proto/app/scripts_dev/process.py", line 80, in _getParsedMatFileData
    parsedMatFileData = _parseMatFileData(rawMatFileData)
  File "/Users/joonyounglee/Code/Data-Visualization-MAPS/AppProto/app_proto/app/scripts_dev/process.py", line 42, in _parseMatFileData
    shape=data[header].shape
KeyError: 'A'
2021-03-29 03:01:14,829 - ERROR - csvmat.py:main method exception. Detailed: KeyError('A')
Traceback (most recent call last):
  File "/Users/joonyounglee/Code/Data-Visualization-MAPS/AppProto/app_proto/app/scripts_dev/logger.py", line 36, in wrapper
    return func(*args, **kwargs)
  File "/Users/joonyounglee/Code/Data-Visualization-MAPS/AppProto/app_proto/app/scripts_dev/process.py", line 163, in main
    processFile(cmdLineArgs)
  File "/Users/joonyounglee/Code/Data-Visualization-MAPS/AppProto/app_proto/app/scripts_dev/process.py", line 156, in processFile
    cmdLineArgs = _addOrigFilePandasDataFrame(cmdLineArgs)
  File "/Users/joonyounglee/Code/Data-Visualization-MAPS/AppProto/app_proto/app/scripts_dev/process.py", line 142, in _addOrigFilePandasDataFrame
    origFilePandasDataFrame = _getOrigFilePandasDataFrame(cmdLineArgs)
  File "/Users/joonyounglee/Code/Data-Visualization-MAPS/AppProto/app_proto/app/scripts_dev/process.py", line 127, in _getOrigFilePandasDataFrame
    return _getPandasDataFrameFromFile(origDataFilePath)
  File "/Users/joonyounglee/Code/Data-Visualization-MAPS/AppProto/app_proto/app/scripts_dev/process.py", line 119, in _getPandasDataFrameFromFile
    return pandasDataFrameProcessor(filePath)
  File "/Users/joonyounglee/Code/Data-Visualization-MAPS/AppProto/app_proto/app/scripts_dev/process.py", line 84, in _handleMATConversionToPandasDataFrame
    parsedMatFileData = _getParsedMatFileData(filePath)
  File "/Users/joonyounglee/Code/Data-Visualization-MAPS/AppProto/app_proto/app/scripts_dev/process.py", line 80, in _getParsedMatFileData
    parsedMatFileData = _parseMatFileData(rawMatFileData)
  File "/Users/joonyounglee/Code/Data-Visualization-MAPS/AppProto/app_proto/app/scripts_dev/process.py", line 42, in _parseMatFileData
    shape=data[header].shape
KeyError: 'A'
2021-03-29 03:03:44,621 - ERROR - csvmat.py:main method exception. Detailed: KeyError('A')
Traceback (most recent call last):
  File "/Users/joonyounglee/Code/Data-Visualization-MAPS/AppProto/app_proto/app/scripts_dev/logger.py", line 36, in wrapper
    return func(*args, **kwargs)
  File "/Users/joonyounglee/Code/Data-Visualization-MAPS/AppProto/app_proto/app/scripts_dev/process.py", line 163, in main
    processFile(cmdLineArgs)
  File "/Users/joonyounglee/Code/Data-Visualization-MAPS/AppProto/app_proto/app/scripts_dev/process.py", line 156, in processFile
    cmdLineArgs = _addOrigFilePandasDataFrame(cmdLineArgs)
  File "/Users/joonyounglee/Code/Data-Visualization-MAPS/AppProto/app_proto/app/scripts_dev/process.py", line 142, in _addOrigFilePandasDataFrame
    origFilePandasDataFrame = _getOrigFilePandasDataFrame(cmdLineArgs)
  File "/Users/joonyounglee/Code/Data-Visualization-MAPS/AppProto/app_proto/app/scripts_dev/process.py", line 127, in _getOrigFilePandasDataFrame
    return _getPandasDataFrameFromFile(origDataFilePath)
  File "/Users/joonyounglee/Code/Data-Visualization-MAPS/AppProto/app_proto/app/scripts_dev/process.py", line 119, in _getPandasDataFrameFromFile
    return pandasDataFrameProcessor(filePath)
  File "/Users/joonyounglee/Code/Data-Visualization-MAPS/AppProto/app_proto/app/scripts_dev/process.py", line 84, in _handleMATConversionToPandasDataFrame
    parsedMatFileData = _getParsedMatFileData(filePath)
  File "/Users/joonyounglee/Code/Data-Visualization-MAPS/AppProto/app_proto/app/scripts_dev/process.py", line 80, in _getParsedMatFileData
    parsedMatFileData = _parseMatFileData(rawMatFileData)
  File "/Users/joonyounglee/Code/Data-Visualization-MAPS/AppProto/app_proto/app/scripts_dev/process.py", line 42, in _parseMatFileData
    shape=data[header].shape
KeyError: 'A'
2021-03-29 03:04:32,449 - ERROR - csvmat.py:main method exception. Detailed: KeyError('A')
Traceback (most recent call last):
  File "/Users/joonyounglee/Code/Data-Visualization-MAPS/AppProto/app_proto/app/scripts_dev/logger.py", line 36, in wrapper
    return func(*args, **kwargs)
  File "/Users/joonyounglee/Code/Data-Visualization-MAPS/AppProto/app_proto/app/scripts_dev/process.py", line 163, in main
    processFile(cmdLineArgs)
  File "/Users/joonyounglee/Code/Data-Visualization-MAPS/AppProto/app_proto/app/scripts_dev/process.py", line 156, in processFile
    cmdLineArgs = _addOrigFilePandasDataFrame(cmdLineArgs)
  File "/Users/joonyounglee/Code/Data-Visualization-MAPS/AppProto/app_proto/app/scripts_dev/process.py", line 142, in _addOrigFilePandasDataFrame
    origFilePandasDataFrame = _getOrigFilePandasDataFrame(cmdLineArgs)
  File "/Users/joonyounglee/Code/Data-Visualization-MAPS/AppProto/app_proto/app/scripts_dev/process.py", line 127, in _getOrigFilePandasDataFrame
    return _getPandasDataFrameFromFile(origDataFilePath)
  File "/Users/joonyounglee/Code/Data-Visualization-MAPS/AppProto/app_proto/app/scripts_dev/process.py", line 119, in _getPandasDataFrameFromFile
    return pandasDataFrameProcessor(filePath)
  File "/Users/joonyounglee/Code/Data-Visualization-MAPS/AppProto/app_proto/app/scripts_dev/process.py", line 84, in _handleMATConversionToPandasDataFrame
    parsedMatFileData = _getParsedMatFileData(filePath)
  File "/Users/joonyounglee/Code/Data-Visualization-MAPS/AppProto/app_proto/app/scripts_dev/process.py", line 80, in _getParsedMatFileData
    parsedMatFileData = _parseMatFileData(rawMatFileData)
  File "/Users/joonyounglee/Code/Data-Visualization-MAPS/AppProto/app_proto/app/scripts_dev/process.py", line 42, in _parseMatFileData
    shape=data[header].shape
KeyError: 'A'
2021-03-29 03:05:06,325 - ERROR - csvmat.py:main method exception. Detailed: KeyError('A')
Traceback (most recent call last):
  File "/Users/joonyounglee/Code/Data-Visualization-MAPS/AppProto/app_proto/app/scripts_dev/logger.py", line 36, in wrapper
    return func(*args, **kwargs)
  File "/Users/joonyounglee/Code/Data-Visualization-MAPS/AppProto/app_proto/app/scripts_dev/process.py", line 163, in main
    processFile(cmdLineArgs)
  File "/Users/joonyounglee/Code/Data-Visualization-MAPS/AppProto/app_proto/app/scripts_dev/process.py", line 156, in processFile
    cmdLineArgs = _addOrigFilePandasDataFrame(cmdLineArgs)
  File "/Users/joonyounglee/Code/Data-Visualization-MAPS/AppProto/app_proto/app/scripts_dev/process.py", line 142, in _addOrigFilePandasDataFrame
    origFilePandasDataFrame = _getOrigFilePandasDataFrame(cmdLineArgs)
  File "/Users/joonyounglee/Code/Data-Visualization-MAPS/AppProto/app_proto/app/scripts_dev/process.py", line 127, in _getOrigFilePandasDataFrame
    return _getPandasDataFrameFromFile(origDataFilePath)
  File "/Users/joonyounglee/Code/Data-Visualization-MAPS/AppProto/app_proto/app/scripts_dev/process.py", line 119, in _getPandasDataFrameFromFile
    return pandasDataFrameProcessor(filePath)
  File "/Users/joonyounglee/Code/Data-Visualization-MAPS/AppProto/app_proto/app/scripts_dev/process.py", line 84, in _handleMATConversionToPandasDataFrame
    parsedMatFileData = _getParsedMatFileData(filePath)
  File "/Users/joonyounglee/Code/Data-Visualization-MAPS/AppProto/app_proto/app/scripts_dev/process.py", line 80, in _getParsedMatFileData
    parsedMatFileData = _parseMatFileData(rawMatFileData)
  File "/Users/joonyounglee/Code/Data-Visualization-MAPS/AppProto/app_proto/app/scripts_dev/process.py", line 42, in _parseMatFileData
    shape=data[header].shape
KeyError: 'A'
2021-03-29 03:10:27,682 - ERROR - csvmat.py:main method exception. Detailed: KeyError('A')
Traceback (most recent call last):
  File "/Users/joonyounglee/Code/Data-Visualization-MAPS/AppProto/app_proto/app/scripts_dev/logger.py", line 36, in wrapper
    return func(*args, **kwargs)
  File "process.py", line 163, in main
    processFile(cmdLineArgs)
  File "process.py", line 156, in processFile
    cmdLineArgs = _addOrigFilePandasDataFrame(cmdLineArgs)
  File "process.py", line 142, in _addOrigFilePandasDataFrame
    origFilePandasDataFrame = _getOrigFilePandasDataFrame(cmdLineArgs)
  File "process.py", line 127, in _getOrigFilePandasDataFrame
    return _getPandasDataFrameFromFile(origDataFilePath)
  File "process.py", line 119, in _getPandasDataFrameFromFile
    return pandasDataFrameProcessor(filePath)
  File "process.py", line 84, in _handleMATConversionToPandasDataFrame
    parsedMatFileData = _getParsedMatFileData(filePath)
  File "process.py", line 80, in _getParsedMatFileData
    parsedMatFileData = _parseMatFileData(rawMatFileData)
  File "process.py", line 42, in _parseMatFileData
    shape=data[header].shape
KeyError: 'A'
2021-03-29 03:12:49,686 - ERROR - csvmat.py:main method exception. Detailed: FileNotFoundError(2, 'No such file or directory')
Traceback (most recent call last):
  File "/Users/joonyounglee/Code/Data-Visualization-MAPS/AppProto/app_proto/app/scripts_dev/logger.py", line 36, in wrapper
    return func(*args, **kwargs)
  File "process.py", line 167, in main
    processFile(cmdLineArgs)
  File "process.py", line 161, in processFile
    _handlePreCalculate(cmdLineArgs)
  File "process.py", line 140, in _handlePreCalculate
    return precalcs.handlePreCalculate(cmdLineArgs)
  File "/Users/joonyounglee/Code/Data-Visualization-MAPS/AppProto/app_proto/app/scripts_dev/precalcs.py", line 334, in handlePreCalculate
    preCalcDataPath = _preCalcAndSave(cmdLineArgs)
  File "/Users/joonyounglee/Code/Data-Visualization-MAPS/AppProto/app_proto/app/scripts_dev/precalcs.py", line 331, in _preCalcAndSave
    _savePreCalcDataFrame(dataFrame, cmdLineArgs)
  File "/Users/joonyounglee/Code/Data-Visualization-MAPS/AppProto/app_proto/app/scripts_dev/precalcs.py", line 24, in _savePreCalcDataFrame
    _savePandasDataFrame(preProcessDataFrame, newDataFilePath)
  File "/Users/joonyounglee/Code/Data-Visualization-MAPS/AppProto/app_proto/app/scripts_dev/precalcs.py", line 16, in _savePandasDataFrame
    pandasHelper.savePandasDataFrame(dataFrame, newDataFilePath)
  File "/Users/joonyounglee/Code/Data-Visualization-MAPS/AppProto/app_proto/app/scripts_dev/helpers/pandasHelper.py", line 26, in savePandasDataFrame
    df.to_csv(filePath)
  File "/Users/joonyounglee/Library/Python/3.8/lib/python/site-packages/pandas/core/generic.py", line 3387, in to_csv
    return DataFrameRenderer(formatter).to_csv(
  File "/Users/joonyounglee/Library/Python/3.8/lib/python/site-packages/pandas/io/formats/format.py", line 1083, in to_csv
    csv_formatter.save()
  File "/Users/joonyounglee/Library/Python/3.8/lib/python/site-packages/pandas/io/formats/csvs.py", line 228, in save
    with get_handle(
  File "/Users/joonyounglee/Library/Python/3.8/lib/python/site-packages/pandas/io/common.py", line 642, in get_handle
    handle = open(
FileNotFoundError: [Errno 2] No such file or directory: '/Users/joonyounglee/Library/Application Support/Electron/save_files/test/eg06_024aprhcalcs.csv'
2021-03-29 03:15:01,628 - ERROR - csvmat.py:main method exception. Detailed: ValueError('could not convert string to float: \'30"\'')
Traceback (most recent call last):
  File "/Users/joonyounglee/Code/Data-Visualization-MAPS/AppProto/app_proto/app/scripts_dev/logger.py", line 36, in wrapper
    return func(*args, **kwargs)
  File "/Users/joonyounglee/Code/Data-Visualization-MAPS/AppProto/app_proto/app/scripts_dev/process.py", line 167, in main
    processFile(cmdLineArgs)
  File "/Users/joonyounglee/Code/Data-Visualization-MAPS/AppProto/app_proto/app/scripts_dev/process.py", line 161, in processFile
    _handlePreCalculate(cmdLineArgs)
  File "/Users/joonyounglee/Code/Data-Visualization-MAPS/AppProto/app_proto/app/scripts_dev/process.py", line 140, in _handlePreCalculate
    return precalcs.handlePreCalculate(cmdLineArgs)
  File "/Users/joonyounglee/Code/Data-Visualization-MAPS/AppProto/app_proto/app/scripts_dev/precalcs.py", line 334, in handlePreCalculate
    preCalcDataPath = _preCalcAndSave(cmdLineArgs)
  File "/Users/joonyounglee/Code/Data-Visualization-MAPS/AppProto/app_proto/app/scripts_dev/precalcs.py", line 330, in _preCalcAndSave
    dataFrame = _preCalc(cmdLineArgs)
  File "/Users/joonyounglee/Code/Data-Visualization-MAPS/AppProto/app_proto/app/scripts_dev/precalcs.py", line 167, in _preCalc
    startLongitude = float(startLongitude)
ValueError: could not convert string to float: '30"'
2021-03-29 03:16:55,498 - ERROR - csvmat.py:main method exception. Detailed: ValueError('could not convert string to float: \'30"\'')
Traceback (most recent call last):
  File "/Users/joonyounglee/Code/Data-Visualization-MAPS/AppProto/app_proto/app/scripts_dev/logger.py", line 36, in wrapper
    return func(*args, **kwargs)
  File "/Users/joonyounglee/Code/Data-Visualization-MAPS/AppProto/app_proto/app/scripts_dev/process.py", line 167, in main
    processFile(cmdLineArgs)
  File "/Users/joonyounglee/Code/Data-Visualization-MAPS/AppProto/app_proto/app/scripts_dev/process.py", line 161, in processFile
    _handlePreCalculate(cmdLineArgs)
  File "/Users/joonyounglee/Code/Data-Visualization-MAPS/AppProto/app_proto/app/scripts_dev/process.py", line 140, in _handlePreCalculate
    return precalcs.handlePreCalculate(cmdLineArgs)
  File "/Users/joonyounglee/Code/Data-Visualization-MAPS/AppProto/app_proto/app/scripts_dev/precalcs.py", line 334, in handlePreCalculate
    preCalcDataPath = _preCalcAndSave(cmdLineArgs)
  File "/Users/joonyounglee/Code/Data-Visualization-MAPS/AppProto/app_proto/app/scripts_dev/precalcs.py", line 330, in _preCalcAndSave
    dataFrame = _preCalc(cmdLineArgs)
  File "/Users/joonyounglee/Code/Data-Visualization-MAPS/AppProto/app_proto/app/scripts_dev/precalcs.py", line 167, in _preCalc
    startLongitude = float(startLongitude)
ValueError: could not convert string to float: '30"'
