2021-03-20 21:31:10,592 - ERROR - csvmat.py:main method exception. Detailed: FileNotFoundError(2, 'No such file or directory')
Traceback (most recent call last):
  File "C:\Users\joonl\Data\Data-Visualization-MAPS\AppProto\app_proto\app\scripts_dev\logger.py", line 36, in wrapper
    return func(*args, **kwargs)
  File ".\process.py", line 163, in main
    processFile(cmdLineArgs)
  File ".\process.py", line 157, in processFile
    _handlePreCalculate(cmdLineArgs)
  File ".\process.py", line 136, in _handlePreCalculate
    return precalcs.handlePreCalculate(cmdLineArgs)
  File "C:\Users\joonl\Data\Data-Visualization-MAPS\AppProto\app_proto\app\scripts_dev\precalcs.py", line 334, in handlePreCalculate
    preCalcDataPath = _preCalcAndSave(cmdLineArgs)
  File "C:\Users\joonl\Data\Data-Visualization-MAPS\AppProto\app_proto\app\scripts_dev\precalcs.py", line 331, in _preCalcAndSave
    _savePreCalcDataFrame(dataFrame, cmdLineArgs)
  File "C:\Users\joonl\Data\Data-Visualization-MAPS\AppProto\app_proto\app\scripts_dev\precalcs.py", line 24, in _savePreCalcDataFrame
    _savePandasDataFrame(preProcessDataFrame, newDataFilePath)
  File "C:\Users\joonl\Data\Data-Visualization-MAPS\AppProto\app_proto\app\scripts_dev\precalcs.py", line 16, in _savePandasDataFrame
    pandasHelper.savePandasDataFrame(dataFrame, newDataFilePath)
  File "C:\Users\joonl\Data\Data-Visualization-MAPS\AppProto\app_proto\app\scripts_dev\helpers\pandasHelper.py", line 26, in savePandasDataFrame
    df.to_csv(filePath)
  File "C:\Users\joonl\AppData\Local\Packages\PythonSoftwareFoundation.Python.3.8_qbz5n2kfra8p0\LocalCache\local-packages\Python38\site-packages\pandas\core\generic.py", line 3170, in to_csv
    formatter.save()
  File "C:\Users\joonl\AppData\Local\Packages\PythonSoftwareFoundation.Python.3.8_qbz5n2kfra8p0\LocalCache\local-packages\Python38\site-packages\pandas\io\formats\csvs.py", line 185, in save
    f, handles = get_handle(
  File "C:\Users\joonl\AppData\Local\Packages\PythonSoftwareFoundation.Python.3.8_qbz5n2kfra8p0\LocalCache\local-packages\Python38\site-packages\pandas\io\common.py", line 493, in get_handle
    f = open(path_or_buf, mode, encoding=encoding, errors=errors, newline="")
FileNotFoundError: [Errno 2] No such file or directory: 'C:\\Users\\joonl\\AppData\\Roaming\\Electron\\save_files\\test2\\gm14_167aprhcalcs.csv'
