2021-01-31 00:00:01,624 - ERROR - csvmat.py:main method exception. Detailed: FileNotFoundError(2, 'No such file or directory')
Traceback (most recent call last):
  File "/Users/joonyounglee/DATA_VIS/Data-Visualization-MAPS/AppProto/app_proto/app/scripts_dev/logger.py", line 36, in wrapper
    return func(*args, **kwargs)
  File "/Users/joonyounglee/DATA_VIS/Data-Visualization-MAPS/AppProto/app_proto/app/scripts_dev/process.py", line 163, in main
    processFile(cmdLineArgs)
  File "/Users/joonyounglee/DATA_VIS/Data-Visualization-MAPS/AppProto/app_proto/app/scripts_dev/process.py", line 157, in processFile
    _handlePreCalculate(cmdLineArgs)
  File "/Users/joonyounglee/DATA_VIS/Data-Visualization-MAPS/AppProto/app_proto/app/scripts_dev/process.py", line 136, in _handlePreCalculate
    return precalcs.handlePreCalculate(cmdLineArgs)
  File "/Users/joonyounglee/DATA_VIS/Data-Visualization-MAPS/AppProto/app_proto/app/scripts_dev/precalcs.py", line 320, in handlePreCalculate
    preCalcDataPath = _preCalcAndSave(cmdLineArgs)
  File "/Users/joonyounglee/DATA_VIS/Data-Visualization-MAPS/AppProto/app_proto/app/scripts_dev/precalcs.py", line 317, in _preCalcAndSave
    _savePreCalcDataFrame(dataFrame, cmdLineArgs)
  File "/Users/joonyounglee/DATA_VIS/Data-Visualization-MAPS/AppProto/app_proto/app/scripts_dev/precalcs.py", line 24, in _savePreCalcDataFrame
    _savePandasDataFrame(preProcessDataFrame, newDataFilePath)
  File "/Users/joonyounglee/DATA_VIS/Data-Visualization-MAPS/AppProto/app_proto/app/scripts_dev/precalcs.py", line 16, in _savePandasDataFrame
    pandasHelper.savePandasDataFrame(dataFrame, newDataFilePath)
  File "/Users/joonyounglee/DATA_VIS/Data-Visualization-MAPS/AppProto/app_proto/app/scripts_dev/helpers/pandasHelper.py", line 26, in savePandasDataFrame
    df.to_csv(filePath)
  File "/Library/Frameworks/Python.framework/Versions/3.8/lib/python3.8/site-packages/pandas/core/generic.py", line 3170, in to_csv
    formatter.save()
  File "/Library/Frameworks/Python.framework/Versions/3.8/lib/python3.8/site-packages/pandas/io/formats/csvs.py", line 185, in save
    f, handles = get_handle(
  File "/Library/Frameworks/Python.framework/Versions/3.8/lib/python3.8/site-packages/pandas/io/common.py", line 493, in get_handle
    f = open(path_or_buf, mode, encoding=encoding, errors=errors, newline="")
FileNotFoundError: [Errno 2] No such file or directory: '/Users/joonyounglee/Library/Application Support/Electron/save_files/gm14_167aprh.mat/gm14_167aprh.matcalcs.csv'
2021-01-31 01:52:52,483 - ERROR - csvmat.py:main method exception. Detailed: FileNotFoundError(2, 'No such file or directory')
Traceback (most recent call last):
  File "/Users/joonyounglee/DATA_VIS/Data-Visualization-MAPS/AppProto/app_proto/app/scripts_dev/logger.py", line 36, in wrapper
    return func(*args, **kwargs)
  File "/Users/joonyounglee/DATA_VIS/Data-Visualization-MAPS/AppProto/app_proto/app/scripts_dev/process.py", line 163, in main
    processFile(cmdLineArgs)
  File "/Users/joonyounglee/DATA_VIS/Data-Visualization-MAPS/AppProto/app_proto/app/scripts_dev/process.py", line 157, in processFile
    _handlePreCalculate(cmdLineArgs)
  File "/Users/joonyounglee/DATA_VIS/Data-Visualization-MAPS/AppProto/app_proto/app/scripts_dev/process.py", line 136, in _handlePreCalculate
    return precalcs.handlePreCalculate(cmdLineArgs)
  File "/Users/joonyounglee/DATA_VIS/Data-Visualization-MAPS/AppProto/app_proto/app/scripts_dev/precalcs.py", line 320, in handlePreCalculate
    preCalcDataPath = _preCalcAndSave(cmdLineArgs)
  File "/Users/joonyounglee/DATA_VIS/Data-Visualization-MAPS/AppProto/app_proto/app/scripts_dev/precalcs.py", line 317, in _preCalcAndSave
    _savePreCalcDataFrame(dataFrame, cmdLineArgs)
  File "/Users/joonyounglee/DATA_VIS/Data-Visualization-MAPS/AppProto/app_proto/app/scripts_dev/precalcs.py", line 24, in _savePreCalcDataFrame
    _savePandasDataFrame(preProcessDataFrame, newDataFilePath)
  File "/Users/joonyounglee/DATA_VIS/Data-Visualization-MAPS/AppProto/app_proto/app/scripts_dev/precalcs.py", line 16, in _savePandasDataFrame
    pandasHelper.savePandasDataFrame(dataFrame, newDataFilePath)
  File "/Users/joonyounglee/DATA_VIS/Data-Visualization-MAPS/AppProto/app_proto/app/scripts_dev/helpers/pandasHelper.py", line 26, in savePandasDataFrame
    df.to_csv(filePath)
  File "/Library/Frameworks/Python.framework/Versions/3.8/lib/python3.8/site-packages/pandas/core/generic.py", line 3170, in to_csv
    formatter.save()
  File "/Library/Frameworks/Python.framework/Versions/3.8/lib/python3.8/site-packages/pandas/io/formats/csvs.py", line 185, in save
    f, handles = get_handle(
  File "/Library/Frameworks/Python.framework/Versions/3.8/lib/python3.8/site-packages/pandas/io/common.py", line 493, in get_handle
    f = open(path_or_buf, mode, encoding=encoding, errors=errors, newline="")
FileNotFoundError: [Errno 2] No such file or directory: '/Users/joonyounglee/Library/Application Support/Electron/save_files/DATA_gm12_172aprh.mat/DATA_gm12_172aprh.matcalcs.csv'
2021-01-31 01:53:33,635 - ERROR - csvmat.py:main method exception. Detailed: FileNotFoundError(2, 'No such file or directory')
Traceback (most recent call last):
  File "/Users/joonyounglee/DATA_VIS/Data-Visualization-MAPS/AppProto/app_proto/app/scripts_dev/logger.py", line 36, in wrapper
    return func(*args, **kwargs)
  File "/Users/joonyounglee/DATA_VIS/Data-Visualization-MAPS/AppProto/app_proto/app/scripts_dev/process.py", line 163, in main
    processFile(cmdLineArgs)
  File "/Users/joonyounglee/DATA_VIS/Data-Visualization-MAPS/AppProto/app_proto/app/scripts_dev/process.py", line 157, in processFile
    _handlePreCalculate(cmdLineArgs)
  File "/Users/joonyounglee/DATA_VIS/Data-Visualization-MAPS/AppProto/app_proto/app/scripts_dev/process.py", line 136, in _handlePreCalculate
    return precalcs.handlePreCalculate(cmdLineArgs)
  File "/Users/joonyounglee/DATA_VIS/Data-Visualization-MAPS/AppProto/app_proto/app/scripts_dev/precalcs.py", line 320, in handlePreCalculate
    preCalcDataPath = _preCalcAndSave(cmdLineArgs)
  File "/Users/joonyounglee/DATA_VIS/Data-Visualization-MAPS/AppProto/app_proto/app/scripts_dev/precalcs.py", line 317, in _preCalcAndSave
    _savePreCalcDataFrame(dataFrame, cmdLineArgs)
  File "/Users/joonyounglee/DATA_VIS/Data-Visualization-MAPS/AppProto/app_proto/app/scripts_dev/precalcs.py", line 24, in _savePreCalcDataFrame
    _savePandasDataFrame(preProcessDataFrame, newDataFilePath)
  File "/Users/joonyounglee/DATA_VIS/Data-Visualization-MAPS/AppProto/app_proto/app/scripts_dev/precalcs.py", line 16, in _savePandasDataFrame
    pandasHelper.savePandasDataFrame(dataFrame, newDataFilePath)
  File "/Users/joonyounglee/DATA_VIS/Data-Visualization-MAPS/AppProto/app_proto/app/scripts_dev/helpers/pandasHelper.py", line 26, in savePandasDataFrame
    df.to_csv(filePath)
  File "/Library/Frameworks/Python.framework/Versions/3.8/lib/python3.8/site-packages/pandas/core/generic.py", line 3170, in to_csv
    formatter.save()
  File "/Library/Frameworks/Python.framework/Versions/3.8/lib/python3.8/site-packages/pandas/io/formats/csvs.py", line 185, in save
    f, handles = get_handle(
  File "/Library/Frameworks/Python.framework/Versions/3.8/lib/python3.8/site-packages/pandas/io/common.py", line 493, in get_handle
    f = open(path_or_buf, mode, encoding=encoding, errors=errors, newline="")
FileNotFoundError: [Errno 2] No such file or directory: '/Users/joonyounglee/Library/Application Support/Electron/save_files/DATA_gm12_172aprh.mat/DATA_gm12_172aprh.matcalcs.csv'
2021-01-31 01:53:34,063 - ERROR - csvmat.py:main method exception. Detailed: FileNotFoundError(2, 'No such file or directory')
Traceback (most recent call last):
  File "/Users/joonyounglee/DATA_VIS/Data-Visualization-MAPS/AppProto/app_proto/app/scripts_dev/logger.py", line 36, in wrapper
    return func(*args, **kwargs)
  File "/Users/joonyounglee/DATA_VIS/Data-Visualization-MAPS/AppProto/app_proto/app/scripts_dev/process.py", line 163, in main
    processFile(cmdLineArgs)
  File "/Users/joonyounglee/DATA_VIS/Data-Visualization-MAPS/AppProto/app_proto/app/scripts_dev/process.py", line 157, in processFile
    _handlePreCalculate(cmdLineArgs)
  File "/Users/joonyounglee/DATA_VIS/Data-Visualization-MAPS/AppProto/app_proto/app/scripts_dev/process.py", line 136, in _handlePreCalculate
    return precalcs.handlePreCalculate(cmdLineArgs)
  File "/Users/joonyounglee/DATA_VIS/Data-Visualization-MAPS/AppProto/app_proto/app/scripts_dev/precalcs.py", line 320, in handlePreCalculate
    preCalcDataPath = _preCalcAndSave(cmdLineArgs)
  File "/Users/joonyounglee/DATA_VIS/Data-Visualization-MAPS/AppProto/app_proto/app/scripts_dev/precalcs.py", line 317, in _preCalcAndSave
    _savePreCalcDataFrame(dataFrame, cmdLineArgs)
  File "/Users/joonyounglee/DATA_VIS/Data-Visualization-MAPS/AppProto/app_proto/app/scripts_dev/precalcs.py", line 24, in _savePreCalcDataFrame
    _savePandasDataFrame(preProcessDataFrame, newDataFilePath)
  File "/Users/joonyounglee/DATA_VIS/Data-Visualization-MAPS/AppProto/app_proto/app/scripts_dev/precalcs.py", line 16, in _savePandasDataFrame
    pandasHelper.savePandasDataFrame(dataFrame, newDataFilePath)
  File "/Users/joonyounglee/DATA_VIS/Data-Visualization-MAPS/AppProto/app_proto/app/scripts_dev/helpers/pandasHelper.py", line 26, in savePandasDataFrame
    df.to_csv(filePath)
  File "/Library/Frameworks/Python.framework/Versions/3.8/lib/python3.8/site-packages/pandas/core/generic.py", line 3170, in to_csv
    formatter.save()
  File "/Library/Frameworks/Python.framework/Versions/3.8/lib/python3.8/site-packages/pandas/io/formats/csvs.py", line 185, in save
    f, handles = get_handle(
  File "/Library/Frameworks/Python.framework/Versions/3.8/lib/python3.8/site-packages/pandas/io/common.py", line 493, in get_handle
    f = open(path_or_buf, mode, encoding=encoding, errors=errors, newline="")
FileNotFoundError: [Errno 2] No such file or directory: '/Users/joonyounglee/Library/Application Support/Electron/save_files/DATA_gm12_172aprh.mat/DATA_gm12_172aprh.matcalcs.csv'
